Exception on /c/d/263548/ [GET]
Traceback (most recent call last):
  File "/home/waqas/m2/m2env/local/lib/python2.7/site-packages/flask/app.py", line 1817, in wsgi_app
    response = self.full_dispatch_request()
  File "/home/waqas/m2/m2env/local/lib/python2.7/site-packages/flask/app.py", line 1477, in full_dispatch_request
    rv = self.handle_user_exception(e)
  File "/home/waqas/m2/m2env/local/lib/python2.7/site-packages/flask/app.py", line 1381, in handle_user_exception
    reraise(exc_type, exc_value, tb)
  File "/home/waqas/m2/m2env/local/lib/python2.7/site-packages/flask/app.py", line 1475, in full_dispatch_request
    rv = self.dispatch_request()
  File "/home/waqas/m2/m2env/local/lib/python2.7/site-packages/flask/app.py", line 1461, in dispatch_request
    return self.view_functions[rule.endpoint](**req.view_args)
  File "/home/waqas/m2/m2env/local/lib/python2.7/site-packages/flask_cache/__init__.py", line 297, in decorated_function
    rv = f(*args, **kwargs)
  File "m2.py", line 78, in show_news
    news = col.find_one({'news_id': nid})
  File "/home/waqas/m2/m2env/local/lib/python2.7/site-packages/pymongo/collection.py", line 798, in find_one
    for result in cursor.limit(-1):
  File "/home/waqas/m2/m2env/local/lib/python2.7/site-packages/pymongo/cursor.py", line 976, in __next__
    if len(self.__data) or self._refresh():
  File "/home/waqas/m2/m2env/local/lib/python2.7/site-packages/pymongo/cursor.py", line 908, in _refresh
    self.__read_preference))
  File "/home/waqas/m2/m2env/local/lib/python2.7/site-packages/pymongo/cursor.py", line 813, in __send_message
    **kwargs)
  File "/home/waqas/m2/m2env/local/lib/python2.7/site-packages/pymongo/mongo_client.py", line 724, in _send_message_with_response
    server = topology.select_server(selector)
  File "/home/waqas/m2/m2env/local/lib/python2.7/site-packages/pymongo/topology.py", line 120, in select_server
    address))
  File "/home/waqas/m2/m2env/local/lib/python2.7/site-packages/pymongo/topology.py", line 96, in select_servers
    self._error_message(selector))
ServerSelectionTimeoutError: localhost:27017: [Errno 111] Connection refused
